<?xml version="1.0" encoding="utf-8"?>
<!-- This URDF was automatically created by SolidWorks to URDF Exporter! Originally created by Stephen Brawner (brawner@gmail.com) 
     Commit Version: 1.6.0-4-g7f85cfe  Build Version: 1.6.7995.38578
     For more information, please see http://wiki.ros.org/sw_urdf_exporter -->
<robot
  name="CAR_ASSEMBLE_URDF">
  <link
    name="base_link">
    <inertial>
      <origin
        xyz="-0.00603422464974022 -0.0210901298715232 0.0524911766865027"
        rpy="0 0 0" />
      <mass
        value="0.190388769252238" />
      <inertia
        ixx="6.83150927298204E-05"
        ixy="-3.24400507185233E-09"
        ixz="8.52921062213978E-09"
        iyy="9.49074699408812E-05"
        iyz="6.22482238337034E-09"
        izz="4.46982601879695E-05" />
    </inertial>
    <visual>
      <origin
        xyz="0 0 0"
        rpy="0 0 0" />
      <geometry>
        <mesh
          filename="package://CAR_ASSEMBLE_URDF/meshes/base_link.STL" />
      </geometry>
      <material
        name="">
        <color
          rgba="0.792156862745098 0.819607843137255 0.933333333333333 1" />
      </material>
    </visual>
    <collision>
      <origin
        xyz="0 0 0"
        rpy="0 0 0" />
      <geometry>
        <mesh
          filename="package://CAR_ASSEMBLE_URDF/meshes/base_link.STL" />
      </geometry>
    </collision>
  </link>
  <link
    name="lidar_link">
    <inertial>
      <origin
        xyz="3.86913161717906E-08 -0.018461643645472 7.75735908079955E-05"
        rpy="0 0 0" />
      <mass
        value="0.10251226954949" />
      <inertia
        ixx="3.53114472561608E-05"
        ixy="2.08391601834097E-11"
        ixz="-2.07482159238868E-11"
        iyy="4.34970025566499E-05"
        iyz="-1.05300166221831E-07"
        izz="3.50508835018759E-05" />
    </inertial>
    <visual>
      <origin
        xyz="0 0 0"
        rpy="0 0 0" />
      <geometry>
        <mesh
          filename="package://CAR_ASSEMBLE_URDF/meshes/lidar_link.STL" />
      </geometry>
      <material
        name="">
        <color
          rgba="0.792156862745098 0.819607843137255 0.933333333333333 1" />
      </material>
    </visual>
    <collision>
      <origin
        xyz="0 0 0"
        rpy="0 0 0" />
      <geometry>
        <mesh
          filename="package://CAR_ASSEMBLE_URDF/meshes/lidar_link.STL" />
      </geometry>
    </collision>
  </link>
  <joint
    name="lidar_joint"
    type="fixed">
    <origin
      xyz="0.0088203 -0.061 0.04267"
      rpy="-1.5708 0 -1.5708" />
    <parent
      link="base_link" />
    <child
      link="lidar_link" />
    <axis
      xyz="0 0 0" />
  </joint>
  <link
    name="front_left_wheel_link">
    <inertial>
      <origin
        xyz="-3.52956049873288E-08 0.0124581724752201 -1.03747976459845E-08"
        rpy="0 0 0" />
      <mass
        value="0.0267991117024946" />
      <inertia
        ixx="2.51782179625165E-06"
        ixy="-1.99045591652718E-12"
        ixz="-5.01991124273091E-12"
        iyy="4.28010615931319E-06"
        iyz="-1.36769997324271E-12"
        izz="2.51785499963632E-06" />
    </inertial>
    <visual>
      <origin
        xyz="0 0 0"
        rpy="0 0 0" />
      <geometry>
        <mesh
          filename="package://CAR_ASSEMBLE_URDF/meshes/front_left_wheel_link.STL" />
      </geometry>
      <material
        name="">
        <color
          rgba="0.752941176470588 0.752941176470588 0.752941176470588 1" />
      </material>
    </visual>
    <collision>
      <origin
        xyz="0 0 0"
        rpy="0 0 0" />
      <geometry>
        <mesh
          filename="package://CAR_ASSEMBLE_URDF/meshes/front_left_wheel_link.STL" />
      </geometry>
    </collision>
  </link>
  <joint
    name="front_left_wheel_joint"
    type="continuous">
    <origin
      xyz="-0.052635 -0.092 -0.041858"
      rpy="-3.1416 0 0" />
    <parent
      link="base_link" />
    <child
      link="front_left_wheel_link" />
    <axis
      xyz="0 1 0" />
  </joint>
  <link
    name="rear_left_wheel_link">
    <inertial>
      <origin
        xyz="-3.47914715093101E-08 0.012458172486175 -1.02828570519575E-08"
        rpy="0 0 0" />
      <mass
        value="0.0267991118389794" />
      <inertia
        ixx="2.5178217761727E-06"
        ixy="-1.95456317954936E-12"
        ixz="-4.986824891805E-12"
        iyy="4.28010619090167E-06"
        iyz="-1.42223968731858E-12"
        izz="2.51785505230012E-06" />
    </inertial>
    <visual>
      <origin
        xyz="0 0 0"
        rpy="0 0 0" />
      <geometry>
        <mesh
          filename="package://CAR_ASSEMBLE_URDF/meshes/rear_left_wheel_link.STL" />
      </geometry>
      <material
        name="">
        <color
          rgba="0.752941176470588 0.752941176470588 0.752941176470588 1" />
      </material>
    </visual>
    <collision>
      <origin
        xyz="0 0 0"
        rpy="0 0 0" />
      <geometry>
        <mesh
          filename="package://CAR_ASSEMBLE_URDF/meshes/rear_left_wheel_link.STL" />
      </geometry>
    </collision>
  </link>
  <joint
    name="rear_left_wheel_joint"
    type="continuous">
    <origin
      xyz="0.043365 -0.096 -0.041858"
      rpy="0 -0.4646 3.1416" />
    <parent
      link="base_link" />
    <child
      link="rear_left_wheel_link" />
    <axis
      xyz="0 1 0" />
  </joint>
  <link
    name="front_right_wheel_link">
    <inertial>
      <origin
        xyz="-3.52956050705955E-08 -0.00554185252478013 -1.03747979027236E-08"
        rpy="0 0 0" />
      <mass
        value="0.0267991117024945" />
      <inertia
        ixx="2.51782179625165E-06"
        ixy="-1.99045590390431E-12"
        ixz="-5.01991124296015E-12"
        iyy="4.28010615931319E-06"
        iyz="-1.36769997270612E-12"
        izz="2.51785499963631E-06" />
    </inertial>
    <visual>
      <origin
        xyz="0 0 0"
        rpy="0 0 0" />
      <geometry>
        <mesh
          filename="package://CAR_ASSEMBLE_URDF/meshes/front_right_wheel_link.STL" />
      </geometry>
      <material
        name="">
        <color
          rgba="0.752941176470588 0.752941176470588 0.752941176470588 1" />
      </material>
    </visual>
    <collision>
      <origin
        xyz="0 0 0"
        rpy="0 0 0" />
      <geometry>
        <mesh
          filename="package://CAR_ASSEMBLE_URDF/meshes/front_right_wheel_link.STL" />
      </geometry>
    </collision>
  </link>
  <joint
    name="front_right_wheel_joint"
    type="continuous">
    <origin
      xyz="-0.052725 0 -0.041858"
      rpy="3.1416 0 -3.1416" />
    <parent
      link="base_link" />
    <child
      link="front_right_wheel_link" />
    <axis
      xyz="0 1 0" />
  </joint>
  <link
    name="rear_right_wheel_link">
    <inertial>
      <origin
        xyz="-3.52956050636566E-08 -0.00554185252478064 -1.03747979721125E-08"
        rpy="0 0 0" />
      <mass
        value="0.0267991117024945" />
      <inertia
        ixx="2.51782179625165E-06"
        ixy="-1.99045590374472E-12"
        ixz="-5.0199112415942E-12"
        iyy="4.28010615931318E-06"
        iyz="-1.36769997283475E-12"
        izz="2.51785499963631E-06" />
    </inertial>
    <visual>
      <origin
        xyz="0 0 0"
        rpy="0 0 0" />
      <geometry>
        <mesh
          filename="package://CAR_ASSEMBLE_URDF/meshes/rear_right_wheel_link.STL" />
      </geometry>
      <material
        name="">
        <color
          rgba="0.752941176470588 0.752941176470588 0.752941176470588 1" />
      </material>
    </visual>
    <collision>
      <origin
        xyz="0 0 0"
        rpy="0 0 0" />
      <geometry>
        <mesh
          filename="package://CAR_ASSEMBLE_URDF/meshes/rear_right_wheel_link.STL" />
      </geometry>
    </collision>
  </link>
  <joint
    name="rear_right_wheel_joint"
    type="continuous">
    <origin
      xyz="0.043275 0 -0.041858"
      rpy="-3.1416 0 3.1416" />
    <parent
      link="base_link" />
    <child
      link="rear_right_wheel_link" />
    <axis
      xyz="0 1 0" />
  </joint>
</robot>